[2023-09-19T19:04:16.974+0000] {taskinstance.py:1157} INFO - Dependencies all met for dep_context=non-requeueable deps ti=<TaskInstance: Reporter.LogProcessor scheduled__2023-09-19T18:50:00+00:00 [queued]>
[2023-09-19T19:04:17.022+0000] {taskinstance.py:1157} INFO - Dependencies all met for dep_context=requeueable deps ti=<TaskInstance: Reporter.LogProcessor scheduled__2023-09-19T18:50:00+00:00 [queued]>
[2023-09-19T19:04:17.033+0000] {taskinstance.py:1359} INFO - Starting attempt 2 of 3
[2023-09-19T19:04:17.075+0000] {taskinstance.py:1380} INFO - Executing <Task(BashOperator): LogProcessor> on 2023-09-19 18:50:00+00:00
[2023-09-19T19:04:17.092+0000] {standard_task_runner.py:57} INFO - Started process 1382 to run task
[2023-09-19T19:04:17.103+0000] {standard_task_runner.py:84} INFO - Running: ['***', 'tasks', 'run', 'Reporter', 'LogProcessor', 'scheduled__2023-09-19T18:50:00+00:00', '--job-id', '51', '--raw', '--subdir', 'DAGS_FOLDER/pipeline.py', '--cfg-path', '/tmp/tmpsbpzrxqr']
[2023-09-19T19:04:17.114+0000] {standard_task_runner.py:85} INFO - Job 51: Subtask LogProcessor
[2023-09-19T19:04:17.229+0000] {task_command.py:415} INFO - Running <TaskInstance: Reporter.LogProcessor scheduled__2023-09-19T18:50:00+00:00 [running]> on host 1a3c67f08000
[2023-09-19T19:04:17.380+0000] {taskinstance.py:1660} INFO - Exporting env vars: AIRFLOW_CTX_DAG_OWNER='***' AIRFLOW_CTX_DAG_ID='Reporter' AIRFLOW_CTX_TASK_ID='LogProcessor' AIRFLOW_CTX_EXECUTION_DATE='2023-09-19T18:50:00+00:00' AIRFLOW_CTX_TRY_NUMBER='2' AIRFLOW_CTX_DAG_RUN_ID='scheduled__2023-09-19T18:50:00+00:00'
[2023-09-19T19:04:17.389+0000] {subprocess.py:63} INFO - Tmp dir root location: /tmp
[2023-09-19T19:04:17.392+0000] {subprocess.py:75} INFO - Running command: ['/bin/bash', '-c', 'python /opt/logs']
[2023-09-19T19:04:17.433+0000] {subprocess.py:86} INFO - Output:
[2023-09-19T19:04:17.650+0000] {subprocess.py:93} INFO - python: can't open file '/opt/logs': [Errno 2] No such file or directory
[2023-09-19T19:04:17.656+0000] {subprocess.py:97} INFO - Command exited with return code 2
[2023-09-19T19:04:17.687+0000] {taskinstance.py:1935} ERROR - Task failed with exception
Traceback (most recent call last):
  File "/home/airflow/.local/lib/python3.8/site-packages/airflow/operators/bash.py", line 210, in execute
    raise AirflowException(
airflow.exceptions.AirflowException: Bash command failed. The command returned a non-zero exit code 2.
[2023-09-19T19:04:17.705+0000] {taskinstance.py:1398} INFO - Marking task as UP_FOR_RETRY. dag_id=Reporter, task_id=LogProcessor, execution_date=20230919T185000, start_date=20230919T190416, end_date=20230919T190417
[2023-09-19T19:04:17.746+0000] {standard_task_runner.py:104} ERROR - Failed to execute job 51 for task LogProcessor (Bash command failed. The command returned a non-zero exit code 2.; 1382)
[2023-09-19T19:04:17.790+0000] {local_task_job_runner.py:228} INFO - Task exited with return code 1
[2023-09-19T19:04:17.830+0000] {taskinstance.py:2776} INFO - 0 downstream tasks scheduled from follow-on schedule check
